 * Serving Flask app 'app'
 * Debug mode: on
[31m[1mWARNING: This is a development server. Do not use it in a production deployment. Use a production WSGI server instead.[0m
 * Running on http://127.0.0.1:5001
[33mPress CTRL+C to quit[0m
 * Restarting with stat
 * Debugger is active!
 * Debugger PIN: 111-750-248
127.0.0.1 - - [25/Jul/2025 07:38:16] "GET /dashboard HTTP/1.1" 200 -
127.0.0.1 - - [25/Jul/2025 07:38:34] "GET /templates HTTP/1.1" 200 -
 * Detected change in '/Users/rcolburn/candidly/tests/test_models.py', reloading
 * Restarting with stat
 * Debugger is active!
 * Debugger PIN: 111-750-248
 * Detected change in '/Users/rcolburn/candidly/tests/test_models.py', reloading
 * Restarting with stat
 * Debugger is active!
 * Debugger PIN: 111-750-248
 * Detected change in '/Users/rcolburn/candidly/tests/conftest.py', reloading
 * Restarting with stat
 * Debugger is active!
 * Debugger PIN: 111-750-248
 * Detected change in '/Users/rcolburn/candidly/tests/conftest.py', reloading
 * Restarting with stat
 * Debugger is active!
 * Debugger PIN: 111-750-248
 * Detected change in '/Users/rcolburn/candidly/tests/test_models.py', reloading
 * Restarting with stat
 * Debugger is active!
 * Debugger PIN: 111-750-248
 * Detected change in '/Users/rcolburn/candidly/tests/test_models.py', reloading
 * Restarting with stat
 * Debugger is active!
 * Debugger PIN: 111-750-248
 * Detected change in '/Users/rcolburn/candidly/tests/test_models.py', reloading
 * Restarting with stat
 * Debugger is active!
 * Debugger PIN: 111-750-248
 * Detected change in '/Users/rcolburn/candidly/tests/test_models.py', reloading
 * Restarting with stat
 * Debugger is active!
 * Debugger PIN: 111-750-248
 * Detected change in '/Users/rcolburn/candidly/tests/test_models.py', reloading
 * Restarting with stat
 * Debugger is active!
 * Debugger PIN: 111-750-248
 * Detected change in '/Users/rcolburn/candidly/tests/test_routes.py', reloading
 * Restarting with stat
 * Debugger is active!
 * Debugger PIN: 111-750-248
 * Detected change in '/Users/rcolburn/candidly/tests/test_routes.py', reloading
 * Restarting with stat
 * Debugger is active!
 * Debugger PIN: 111-750-248
 * Detected change in '/Users/rcolburn/candidly/tests/test_routes.py', reloading
 * Restarting with stat
 * Debugger is active!
 * Debugger PIN: 111-750-248
 * Detected change in '/Users/rcolburn/candidly/tests/test_routes.py', reloading
 * Restarting with stat
 * Debugger is active!
 * Debugger PIN: 111-750-248
 * Detected change in '/Users/rcolburn/candidly/tests/test_routes.py', reloading
 * Restarting with stat
 * Debugger is active!
 * Debugger PIN: 111-750-248
 * Detected change in '/Users/rcolburn/candidly/tests/test_routes.py', reloading
 * Restarting with stat
 * Debugger is active!
 * Debugger PIN: 111-750-248
 * Detected change in '/Users/rcolburn/candidly/tests/test_routes.py', reloading
 * Restarting with stat
 * Debugger is active!
 * Debugger PIN: 111-750-248
 * Detected change in '/Users/rcolburn/candidly/tests/test_models.py', reloading
 * Restarting with stat
 * Debugger is active!
 * Debugger PIN: 111-750-248
 * Detected change in '/Users/rcolburn/candidly/tests/test_models.py', reloading
 * Restarting with stat
 * Debugger is active!
 * Debugger PIN: 111-750-248
 * Detected change in '/Users/rcolburn/candidly/tests/test_models.py', reloading
 * Restarting with stat
 * Debugger is active!
 * Debugger PIN: 111-750-248
 * Detected change in '/Users/rcolburn/candidly/tests/test_models.py', reloading
 * Restarting with stat
 * Debugger is active!
 * Debugger PIN: 111-750-248
 * Detected change in '/Users/rcolburn/candidly/tests/test_integration.py', reloading
 * Restarting with stat
 * Debugger is active!
 * Debugger PIN: 111-750-248
 * Detected change in '/Users/rcolburn/candidly/tests/test_integration.py', reloading
 * Restarting with stat
 * Debugger is active!
 * Debugger PIN: 111-750-248
 * Detected change in '/Users/rcolburn/candidly/tests/test_integration.py', reloading
 * Restarting with stat
 * Debugger is active!
 * Debugger PIN: 111-750-248
 * Detected change in '/Users/rcolburn/candidly/tests/test_integration.py', reloading
 * Restarting with stat
 * Debugger is active!
 * Debugger PIN: 111-750-248
 * Detected change in '/Users/rcolburn/candidly/tests/test_integration.py', reloading
 * Restarting with stat
 * Debugger is active!
 * Debugger PIN: 111-750-248
 * Detected change in '/Users/rcolburn/candidly/tests/test_integration.py', reloading
 * Restarting with stat
 * Debugger is active!
 * Debugger PIN: 111-750-248
 * Detected change in '/Users/rcolburn/candidly/tests/test_integration.py', reloading
 * Restarting with stat
 * Debugger is active!
 * Debugger PIN: 111-750-248
127.0.0.1 - - [25/Jul/2025 07:58:40] "GET / HTTP/1.1" 200 -
127.0.0.1 - - [25/Jul/2025 07:58:53] "GET /templates HTTP/1.1" 200 -
127.0.0.1 - - [25/Jul/2025 07:58:55] "GET /templates/create HTTP/1.1" 200 -
127.0.0.1 - - [25/Jul/2025 07:59:30] "[32mPOST /templates/create HTTP/1.1[0m" 302 -
127.0.0.1 - - [25/Jul/2025 07:59:30] "GET /templates HTTP/1.1" 200 -
127.0.0.1 - - [25/Jul/2025 07:59:33] "GET /create?template=131d3a81-a036-4df6-8c41-3f448ec48e43 HTTP/1.1" 200 -
127.0.0.1 - - [25/Jul/2025 07:59:41] "[32mPOST /create?template=131d3a81-a036-4df6-8c41-3f448ec48e43 HTTP/1.1[0m" 302 -
127.0.0.1 - - [25/Jul/2025 07:59:41] "GET /share/82d9b100-109a-4a64-a22e-f8d1481a12bb HTTP/1.1" 200 -
127.0.0.1 - - [25/Jul/2025 07:59:44] "GET /survey/82d9b100-109a-4a64-a22e-f8d1481a12bb HTTP/1.1" 200 -
127.0.0.1 - - [25/Jul/2025 07:59:57] "POST /api/chat/e6b28b94-f624-4adb-a1df-bddb856736a6 HTTP/1.1" 200 -
127.0.0.1 - - [25/Jul/2025 08:00:07] "POST /api/chat/e6b28b94-f624-4adb-a1df-bddb856736a6 HTTP/1.1" 200 -
127.0.0.1 - - [25/Jul/2025 08:00:16] "POST /api/chat/e6b28b94-f624-4adb-a1df-bddb856736a6 HTTP/1.1" 200 -
127.0.0.1 - - [25/Jul/2025 08:00:39] "POST /api/chat/e6b28b94-f624-4adb-a1df-bddb856736a6 HTTP/1.1" 200 -
127.0.0.1 - - [25/Jul/2025 08:00:42] "POST /review/82d9b100-109a-4a64-a22e-f8d1481a12bb HTTP/1.1" 200 -
127.0.0.1 - - [25/Jul/2025 08:00:42] "GET /review/82d9b100-109a-4a64-a22e-f8d1481a12bb HTTP/1.1" 200 -
/Users/rcolburn/candidly/app.py:191: DeprecationWarning: datetime.datetime.utcnow() is deprecated and scheduled for removal in a future version. Use timezone-aware objects to represent datetimes in UTC: datetime.datetime.now(datetime.UTC).
  response.submitted_at = datetime.utcnow()
127.0.0.1 - - [25/Jul/2025 08:00:47] "[32mPOST /submit/82d9b100-109a-4a64-a22e-f8d1481a12bb HTTP/1.1[0m" 302 -
127.0.0.1 - - [25/Jul/2025 08:00:47] "GET /thank-you HTTP/1.1" 200 -
127.0.0.1 - - [25/Jul/2025 08:00:49] "GET / HTTP/1.1" 200 -
127.0.0.1 - - [25/Jul/2025 08:13:43] "GET /dashboard HTTP/1.1" 200 -
127.0.0.1 - - [25/Jul/2025 08:13:48] "GET /report/82d9b100-109a-4a64-a22e-f8d1481a12bb HTTP/1.1" 200 -
127.0.0.1 - - [25/Jul/2025 08:14:51] "[35m[1mGET /dashboard HTTP/1.1[0m" 500 -
Traceback (most recent call last):
  File "/Users/rcolburn/candidly/venv/lib/python3.13/site-packages/sqlalchemy/engine/base.py", line 1963, in _exec_single_context
    self.dialect.do_execute(
    ^
  File "/Users/rcolburn/candidly/venv/lib/python3.13/site-packages/sqlalchemy/engine/default.py", line 943, in do_execute
    cursor.execute(statement, parameters)
    ~~~~~~~~~~~~~~^^^^^^^^^^^^^^^^^^^^^^^
sqlite3.OperationalError: no such table: feedback_request

The above exception was the direct cause of the following exception:

Traceback (most recent call last):
  File "/Users/rcolburn/candidly/venv/lib/python3.13/site-packages/flask/app.py", line 2213, in __call__
    return self.wsgi_app(environ, start_response)
           ~~~~~~~~~~~~~^^^^^^^^^^^^^^^^^^^^^^^^^
  File "/Users/rcolburn/candidly/venv/lib/python3.13/site-packages/flask/app.py", line 2193, in wsgi_app
    response = self.handle_exception(e)
  File "/Users/rcolburn/candidly/venv/lib/python3.13/site-packages/flask/app.py", line 2190, in wsgi_app
    response = self.full_dispatch_request()
  File "/Users/rcolburn/candidly/venv/lib/python3.13/site-packages/flask/app.py", line 1486, in full_dispatch_request
    rv = self.handle_user_exception(e)
  File "/Users/rcolburn/candidly/venv/lib/python3.13/site-packages/flask/app.py", line 1484, in full_dispatch_request
    rv = self.dispatch_request()
  File "/Users/rcolburn/candidly/venv/lib/python3.13/site-packages/flask/app.py", line 1469, in dispatch_request
    return self.ensure_sync(self.view_functions[rule.endpoint])(**view_args)
           ~~~~~~~~~~~~~~~~~~~~~~~~~~~~~~~~~~~~~~~~~~~~~~~~~~~~^^^^^^^^^^^^^
  File "/Users/rcolburn/candidly/app.py", line 204, in dashboard
    feedback_requests = FeedbackRequest.query.order_by(FeedbackRequest.created_at.desc()).all()
  File "/Users/rcolburn/candidly/venv/lib/python3.13/site-packages/sqlalchemy/orm/query.py", line 2704, in all
    return self._iter().all()  # type: ignore
           ~~~~~~~~~~^^
  File "/Users/rcolburn/candidly/venv/lib/python3.13/site-packages/sqlalchemy/orm/query.py", line 2857, in _iter
    result: Union[ScalarResult[_T], Result[_T]] = self.session.execute(
    
  File "/Users/rcolburn/candidly/venv/lib/python3.13/site-packages/sqlalchemy/orm/session.py", line 2365, in execute
    return self._execute_internal(
    
  File "/Users/rcolburn/candidly/venv/lib/python3.13/site-packages/sqlalchemy/orm/session.py", line 2251, in _execute_internal
    result: Result[Any] = compile_state_cls.orm_execute_statement(
    
  File "/Users/rcolburn/candidly/venv/lib/python3.13/site-packages/sqlalchemy/orm/context.py", line 306, in orm_execute_statement
    result = conn.execute(
    
  File "/Users/rcolburn/candidly/venv/lib/python3.13/site-packages/sqlalchemy/engine/base.py", line 1415, in execute
    return meth(
    
  File "/Users/rcolburn/candidly/venv/lib/python3.13/site-packages/sqlalchemy/sql/elements.py", line 523, in _execute_on_connection
    return connection._execute_clauseelement(
    
  File "/Users/rcolburn/candidly/venv/lib/python3.13/site-packages/sqlalchemy/engine/base.py", line 1637, in _execute_clauseelement
    ret = self._execute_context(
    
  File "/Users/rcolburn/candidly/venv/lib/python3.13/site-packages/sqlalchemy/engine/base.py", line 1842, in _execute_context
    return self._exec_single_context(
    
  File "/Users/rcolburn/candidly/venv/lib/python3.13/site-packages/sqlalchemy/engine/base.py", line 1982, in _exec_single_context
    self._handle_dbapi_exception(
    ^
  File "/Users/rcolburn/candidly/venv/lib/python3.13/site-packages/sqlalchemy/engine/base.py", line 2351, in _handle_dbapi_exception
    raise sqlalchemy_exception.with_traceback(exc_info[2]) from e
  File "/Users/rcolburn/candidly/venv/lib/python3.13/site-packages/sqlalchemy/engine/base.py", line 1963, in _exec_single_context
    self.dialect.do_execute(
    ^
  File "/Users/rcolburn/candidly/venv/lib/python3.13/site-packages/sqlalchemy/engine/default.py", line 943, in do_execute
    cursor.execute(statement, parameters)
    ~~~~~~~~~~~~~~^^^^^^^^^^^^^^^^^^^^^^^
sqlalchemy.exc.OperationalError: (sqlite3.OperationalError) no such table: feedback_request
[SQL: SELECT feedback_request.id AS feedback_request_id, feedback_request.target_name AS feedback_request_target_name, feedback_request.template_id AS feedback_request_template_id, feedback_request.created_at AS feedback_request_created_at 
FROM feedback_request ORDER BY feedback_request.created_at DESC]
(Background on this error at: https://sqlalche.me/e/20/e3q8)
127.0.0.1 - - [25/Jul/2025 08:14:51] "[36mGET /dashboard?__debugger__=yes&cmd=resource&f=debugger.js HTTP/1.1[0m" 304 -
127.0.0.1 - - [25/Jul/2025 08:14:51] "[36mGET /dashboard?__debugger__=yes&cmd=resource&f=style.css HTTP/1.1[0m" 304 -
127.0.0.1 - - [25/Jul/2025 08:14:51] "GET /dashboard?__debugger__=yes&cmd=resource&f=console.png&s=5rIHpUI3vf98iIB7tjKT HTTP/1.1" 200 -
127.0.0.1 - - [25/Jul/2025 08:14:51] "[36mGET /dashboard?__debugger__=yes&cmd=resource&f=console.png HTTP/1.1[0m" 304 -
127.0.0.1 - - [25/Jul/2025 08:15:47] "GET /dashboard HTTP/1.1" 200 -
127.0.0.1 - - [25/Jul/2025 08:16:34] "[35m[1mGET /create HTTP/1.1[0m" 500 -
Traceback (most recent call last):
  File "/Users/rcolburn/candidly/venv/lib/python3.13/site-packages/sqlalchemy/engine/base.py", line 1963, in _exec_single_context
    self.dialect.do_execute(
    ^
  File "/Users/rcolburn/candidly/venv/lib/python3.13/site-packages/sqlalchemy/engine/default.py", line 943, in do_execute
    cursor.execute(statement, parameters)
    ~~~~~~~~~~~~~~^^^^^^^^^^^^^^^^^^^^^^^
sqlite3.OperationalError: no such table: feedback_template

The above exception was the direct cause of the following exception:

Traceback (most recent call last):
  File "/Users/rcolburn/candidly/venv/lib/python3.13/site-packages/flask/app.py", line 2213, in __call__
    return self.wsgi_app(environ, start_response)
           ~~~~~~~~~~~~~^^^^^^^^^^^^^^^^^^^^^^^^^
  File "/Users/rcolburn/candidly/venv/lib/python3.13/site-packages/flask/app.py", line 2193, in wsgi_app
    response = self.handle_exception(e)
  File "/Users/rcolburn/candidly/venv/lib/python3.13/site-packages/flask/app.py", line 2190, in wsgi_app
    response = self.full_dispatch_request()
  File "/Users/rcolburn/candidly/venv/lib/python3.13/site-packages/flask/app.py", line 1486, in full_dispatch_request
    rv = self.handle_user_exception(e)
  File "/Users/rcolburn/candidly/venv/lib/python3.13/site-packages/flask/app.py", line 1484, in full_dispatch_request
    rv = self.dispatch_request()
  File "/Users/rcolburn/candidly/venv/lib/python3.13/site-packages/flask/app.py", line 1469, in dispatch_request
    return self.ensure_sync(self.view_functions[rule.endpoint])(**view_args)
           ~~~~~~~~~~~~~~~~~~~~~~~~~~~~~~~~~~~~~~~~~~~~~~~~~~~~^^^^^^^^^^^^^
  File "/Users/rcolburn/candidly/app.py", line 80, in create_request
    templates = FeedbackTemplate.query.order_by(FeedbackTemplate.name).all()
  File "/Users/rcolburn/candidly/venv/lib/python3.13/site-packages/sqlalchemy/orm/query.py", line 2704, in all
    return self._iter().all()  # type: ignore
           ~~~~~~~~~~^^
  File "/Users/rcolburn/candidly/venv/lib/python3.13/site-packages/sqlalchemy/orm/query.py", line 2857, in _iter
    result: Union[ScalarResult[_T], Result[_T]] = self.session.execute(
    
  File "/Users/rcolburn/candidly/venv/lib/python3.13/site-packages/sqlalchemy/orm/session.py", line 2365, in execute
    return self._execute_internal(
    
  File "/Users/rcolburn/candidly/venv/lib/python3.13/site-packages/sqlalchemy/orm/session.py", line 2251, in _execute_internal
    result: Result[Any] = compile_state_cls.orm_execute_statement(
    
  File "/Users/rcolburn/candidly/venv/lib/python3.13/site-packages/sqlalchemy/orm/context.py", line 306, in orm_execute_statement
    result = conn.execute(
    
  File "/Users/rcolburn/candidly/venv/lib/python3.13/site-packages/sqlalchemy/engine/base.py", line 1415, in execute
    return meth(
    
  File "/Users/rcolburn/candidly/venv/lib/python3.13/site-packages/sqlalchemy/sql/elements.py", line 523, in _execute_on_connection
    return connection._execute_clauseelement(
    
  File "/Users/rcolburn/candidly/venv/lib/python3.13/site-packages/sqlalchemy/engine/base.py", line 1637, in _execute_clauseelement
    ret = self._execute_context(
    
  File "/Users/rcolburn/candidly/venv/lib/python3.13/site-packages/sqlalchemy/engine/base.py", line 1842, in _execute_context
    return self._exec_single_context(
    
  File "/Users/rcolburn/candidly/venv/lib/python3.13/site-packages/sqlalchemy/engine/base.py", line 1982, in _exec_single_context
    self._handle_dbapi_exception(
    ^
  File "/Users/rcolburn/candidly/venv/lib/python3.13/site-packages/sqlalchemy/engine/base.py", line 2351, in _handle_dbapi_exception
    raise sqlalchemy_exception.with_traceback(exc_info[2]) from e
  File "/Users/rcolburn/candidly/venv/lib/python3.13/site-packages/sqlalchemy/engine/base.py", line 1963, in _exec_single_context
    self.dialect.do_execute(
    ^
  File "/Users/rcolburn/candidly/venv/lib/python3.13/site-packages/sqlalchemy/engine/default.py", line 943, in do_execute
    cursor.execute(statement, parameters)
    ~~~~~~~~~~~~~~^^^^^^^^^^^^^^^^^^^^^^^
sqlalchemy.exc.OperationalError: (sqlite3.OperationalError) no such table: feedback_template
[SQL: SELECT feedback_template.id AS feedback_template_id, feedback_template.name AS feedback_template_name, feedback_template.description AS feedback_template_description, feedback_template.created_at AS feedback_template_created_at 
FROM feedback_template ORDER BY feedback_template.name]
(Background on this error at: https://sqlalche.me/e/20/e3q8)
127.0.0.1 - - [25/Jul/2025 08:16:34] "GET /create?__debugger__=yes&cmd=resource&f=debugger.js HTTP/1.1" 200 -
127.0.0.1 - - [25/Jul/2025 08:16:34] "GET /create?__debugger__=yes&cmd=resource&f=style.css HTTP/1.1" 200 -
127.0.0.1 - - [25/Jul/2025 08:16:34] "GET /create?__debugger__=yes&cmd=resource&f=console.png&s=5rIHpUI3vf98iIB7tjKT HTTP/1.1" 200 -
127.0.0.1 - - [25/Jul/2025 08:16:34] "GET /create?__debugger__=yes&cmd=resource&f=console.png HTTP/1.1" 200 -
127.0.0.1 - - [25/Jul/2025 08:18:01] "[35m[1mGET /create HTTP/1.1[0m" 500 -
Traceback (most recent call last):
  File "/Users/rcolburn/candidly/venv/lib/python3.13/site-packages/sqlalchemy/engine/base.py", line 1963, in _exec_single_context
    self.dialect.do_execute(
    ^
  File "/Users/rcolburn/candidly/venv/lib/python3.13/site-packages/sqlalchemy/engine/default.py", line 943, in do_execute
    cursor.execute(statement, parameters)
    ~~~~~~~~~~~~~~^^^^^^^^^^^^^^^^^^^^^^^
sqlite3.OperationalError: no such table: feedback_template

The above exception was the direct cause of the following exception:

Traceback (most recent call last):
  File "/Users/rcolburn/candidly/venv/lib/python3.13/site-packages/flask/app.py", line 2213, in __call__
    return self.wsgi_app(environ, start_response)
           ~~~~~~~~~~~~~^^^^^^^^^^^^^^^^^^^^^^^^^
  File "/Users/rcolburn/candidly/venv/lib/python3.13/site-packages/flask/app.py", line 2193, in wsgi_app
    response = self.handle_exception(e)
  File "/Users/rcolburn/candidly/venv/lib/python3.13/site-packages/flask/app.py", line 2190, in wsgi_app
    response = self.full_dispatch_request()
  File "/Users/rcolburn/candidly/venv/lib/python3.13/site-packages/flask/app.py", line 1486, in full_dispatch_request
    rv = self.handle_user_exception(e)
  File "/Users/rcolburn/candidly/venv/lib/python3.13/site-packages/flask/app.py", line 1484, in full_dispatch_request
    rv = self.dispatch_request()
  File "/Users/rcolburn/candidly/venv/lib/python3.13/site-packages/flask/app.py", line 1469, in dispatch_request
    return self.ensure_sync(self.view_functions[rule.endpoint])(**view_args)
           ~~~~~~~~~~~~~~~~~~~~~~~~~~~~~~~~~~~~~~~~~~~~~~~~~~~~^^^^^^^^^^^^^
  File "/Users/rcolburn/candidly/app.py", line 80, in create_request
    templates = FeedbackTemplate.query.order_by(FeedbackTemplate.name).all()
  File "/Users/rcolburn/candidly/venv/lib/python3.13/site-packages/sqlalchemy/orm/query.py", line 2704, in all
    return self._iter().all()  # type: ignore
           ~~~~~~~~~~^^
  File "/Users/rcolburn/candidly/venv/lib/python3.13/site-packages/sqlalchemy/orm/query.py", line 2857, in _iter
    result: Union[ScalarResult[_T], Result[_T]] = self.session.execute(
    
  File "/Users/rcolburn/candidly/venv/lib/python3.13/site-packages/sqlalchemy/orm/session.py", line 2365, in execute
    return self._execute_internal(
    
  File "/Users/rcolburn/candidly/venv/lib/python3.13/site-packages/sqlalchemy/orm/session.py", line 2251, in _execute_internal
    result: Result[Any] = compile_state_cls.orm_execute_statement(
    
  File "/Users/rcolburn/candidly/venv/lib/python3.13/site-packages/sqlalchemy/orm/context.py", line 306, in orm_execute_statement
    result = conn.execute(
    
  File "/Users/rcolburn/candidly/venv/lib/python3.13/site-packages/sqlalchemy/engine/base.py", line 1415, in execute
    return meth(
    
  File "/Users/rcolburn/candidly/venv/lib/python3.13/site-packages/sqlalchemy/sql/elements.py", line 523, in _execute_on_connection
    return connection._execute_clauseelement(
    
  File "/Users/rcolburn/candidly/venv/lib/python3.13/site-packages/sqlalchemy/engine/base.py", line 1637, in _execute_clauseelement
    ret = self._execute_context(
    
  File "/Users/rcolburn/candidly/venv/lib/python3.13/site-packages/sqlalchemy/engine/base.py", line 1842, in _execute_context
    return self._exec_single_context(
    
  File "/Users/rcolburn/candidly/venv/lib/python3.13/site-packages/sqlalchemy/engine/base.py", line 1982, in _exec_single_context
    self._handle_dbapi_exception(
    ^
  File "/Users/rcolburn/candidly/venv/lib/python3.13/site-packages/sqlalchemy/engine/base.py", line 2351, in _handle_dbapi_exception
    raise sqlalchemy_exception.with_traceback(exc_info[2]) from e
  File "/Users/rcolburn/candidly/venv/lib/python3.13/site-packages/sqlalchemy/engine/base.py", line 1963, in _exec_single_context
    self.dialect.do_execute(
    ^
  File "/Users/rcolburn/candidly/venv/lib/python3.13/site-packages/sqlalchemy/engine/default.py", line 943, in do_execute
    cursor.execute(statement, parameters)
    ~~~~~~~~~~~~~~^^^^^^^^^^^^^^^^^^^^^^^
sqlalchemy.exc.OperationalError: (sqlite3.OperationalError) no such table: feedback_template
[SQL: SELECT feedback_template.id AS feedback_template_id, feedback_template.name AS feedback_template_name, feedback_template.description AS feedback_template_description, feedback_template.created_at AS feedback_template_created_at 
FROM feedback_template ORDER BY feedback_template.name]
(Background on this error at: https://sqlalche.me/e/20/e3q8)
127.0.0.1 - - [25/Jul/2025 08:18:01] "[36mGET /create?__debugger__=yes&cmd=resource&f=style.css HTTP/1.1[0m" 304 -
127.0.0.1 - - [25/Jul/2025 08:18:01] "[36mGET /create?__debugger__=yes&cmd=resource&f=debugger.js HTTP/1.1[0m" 304 -
127.0.0.1 - - [25/Jul/2025 08:18:01] "[36mGET /create?__debugger__=yes&cmd=resource&f=console.png&s=5rIHpUI3vf98iIB7tjKT HTTP/1.1[0m" 304 -
127.0.0.1 - - [25/Jul/2025 08:18:01] "[36mGET /create?__debugger__=yes&cmd=resource&f=console.png HTTP/1.1[0m" 304 -
127.0.0.1 - - [25/Jul/2025 08:18:05] "[35m[1mGET /dashboard HTTP/1.1[0m" 500 -
Traceback (most recent call last):
  File "/Users/rcolburn/candidly/venv/lib/python3.13/site-packages/sqlalchemy/engine/base.py", line 1963, in _exec_single_context
    self.dialect.do_execute(
    ^
  File "/Users/rcolburn/candidly/venv/lib/python3.13/site-packages/sqlalchemy/engine/default.py", line 943, in do_execute
    cursor.execute(statement, parameters)
    ~~~~~~~~~~~~~~^^^^^^^^^^^^^^^^^^^^^^^
sqlite3.OperationalError: no such table: feedback_request

The above exception was the direct cause of the following exception:

Traceback (most recent call last):
  File "/Users/rcolburn/candidly/venv/lib/python3.13/site-packages/flask/app.py", line 2213, in __call__
    return self.wsgi_app(environ, start_response)
           ~~~~~~~~~~~~~^^^^^^^^^^^^^^^^^^^^^^^^^
  File "/Users/rcolburn/candidly/venv/lib/python3.13/site-packages/flask/app.py", line 2193, in wsgi_app
    response = self.handle_exception(e)
  File "/Users/rcolburn/candidly/venv/lib/python3.13/site-packages/flask/app.py", line 2190, in wsgi_app
    response = self.full_dispatch_request()
  File "/Users/rcolburn/candidly/venv/lib/python3.13/site-packages/flask/app.py", line 1486, in full_dispatch_request
    rv = self.handle_user_exception(e)
  File "/Users/rcolburn/candidly/venv/lib/python3.13/site-packages/flask/app.py", line 1484, in full_dispatch_request
    rv = self.dispatch_request()
  File "/Users/rcolburn/candidly/venv/lib/python3.13/site-packages/flask/app.py", line 1469, in dispatch_request
    return self.ensure_sync(self.view_functions[rule.endpoint])(**view_args)
           ~~~~~~~~~~~~~~~~~~~~~~~~~~~~~~~~~~~~~~~~~~~~~~~~~~~~^^^^^^^^^^^^^
  File "/Users/rcolburn/candidly/app.py", line 204, in dashboard
    feedback_requests = FeedbackRequest.query.order_by(FeedbackRequest.created_at.desc()).all()
  File "/Users/rcolburn/candidly/venv/lib/python3.13/site-packages/sqlalchemy/orm/query.py", line 2704, in all
    return self._iter().all()  # type: ignore
           ~~~~~~~~~~^^
  File "/Users/rcolburn/candidly/venv/lib/python3.13/site-packages/sqlalchemy/orm/query.py", line 2857, in _iter
    result: Union[ScalarResult[_T], Result[_T]] = self.session.execute(
    
  File "/Users/rcolburn/candidly/venv/lib/python3.13/site-packages/sqlalchemy/orm/session.py", line 2365, in execute
    return self._execute_internal(
    
  File "/Users/rcolburn/candidly/venv/lib/python3.13/site-packages/sqlalchemy/orm/session.py", line 2251, in _execute_internal
    result: Result[Any] = compile_state_cls.orm_execute_statement(
    
  File "/Users/rcolburn/candidly/venv/lib/python3.13/site-packages/sqlalchemy/orm/context.py", line 306, in orm_execute_statement
    result = conn.execute(
    
  File "/Users/rcolburn/candidly/venv/lib/python3.13/site-packages/sqlalchemy/engine/base.py", line 1415, in execute
    return meth(
    
  File "/Users/rcolburn/candidly/venv/lib/python3.13/site-packages/sqlalchemy/sql/elements.py", line 523, in _execute_on_connection
    return connection._execute_clauseelement(
    
  File "/Users/rcolburn/candidly/venv/lib/python3.13/site-packages/sqlalchemy/engine/base.py", line 1637, in _execute_clauseelement
    ret = self._execute_context(
    
  File "/Users/rcolburn/candidly/venv/lib/python3.13/site-packages/sqlalchemy/engine/base.py", line 1842, in _execute_context
    return self._exec_single_context(
    
  File "/Users/rcolburn/candidly/venv/lib/python3.13/site-packages/sqlalchemy/engine/base.py", line 1982, in _exec_single_context
    self._handle_dbapi_exception(
    ^
  File "/Users/rcolburn/candidly/venv/lib/python3.13/site-packages/sqlalchemy/engine/base.py", line 2351, in _handle_dbapi_exception
    raise sqlalchemy_exception.with_traceback(exc_info[2]) from e
  File "/Users/rcolburn/candidly/venv/lib/python3.13/site-packages/sqlalchemy/engine/base.py", line 1963, in _exec_single_context
    self.dialect.do_execute(
    ^
  File "/Users/rcolburn/candidly/venv/lib/python3.13/site-packages/sqlalchemy/engine/default.py", line 943, in do_execute
    cursor.execute(statement, parameters)
    ~~~~~~~~~~~~~~^^^^^^^^^^^^^^^^^^^^^^^
sqlalchemy.exc.OperationalError: (sqlite3.OperationalError) no such table: feedback_request
[SQL: SELECT feedback_request.id AS feedback_request_id, feedback_request.target_name AS feedback_request_target_name, feedback_request.template_id AS feedback_request_template_id, feedback_request.created_at AS feedback_request_created_at 
FROM feedback_request ORDER BY feedback_request.created_at DESC]
(Background on this error at: https://sqlalche.me/e/20/e3q8)
127.0.0.1 - - [25/Jul/2025 08:18:05] "[36mGET /dashboard?__debugger__=yes&cmd=resource&f=style.css HTTP/1.1[0m" 304 -
127.0.0.1 - - [25/Jul/2025 08:18:05] "[36mGET /dashboard?__debugger__=yes&cmd=resource&f=debugger.js HTTP/1.1[0m" 304 -
127.0.0.1 - - [25/Jul/2025 08:18:05] "[36mGET /dashboard?__debugger__=yes&cmd=resource&f=console.png&s=5rIHpUI3vf98iIB7tjKT HTTP/1.1[0m" 304 -
127.0.0.1 - - [25/Jul/2025 08:18:05] "[36mGET /dashboard?__debugger__=yes&cmd=resource&f=console.png HTTP/1.1[0m" 304 -
